Workbook
Name p2_start: 'Параметри ЛР2'!$C$2
Name p2_hours: 'Параметри ЛР2'!$C$3
Name p2_focus: 'Параметри ЛР2'!$C$4
Name p2_days_week: 'Параметри ЛР2'!$C$5
Name p2_z80: 'Параметри ЛР2'!$C$6
Name p2_backlog: 'Параметри ЛР2'!$C$7
Name p2_sprint: 'Параметри ЛР2'!$C$8
Name p2_tcf: 'Параметри ЛР2'!$C$9
Name p2_ecf: 'Параметри ЛР2'!$C$10
Name p2_pf: 'Параметри ЛР2'!$C$11
Name p2_util: 'Параметри ЛР2'!$C$12
Name p2_mr: 'Параметри ЛР2'!$C$13
Name p2_mc_p50: 'Параметри ЛР2'!$C$14
Name p2_mc_p80: 'Параметри ЛР2'!$C$15
Name p2_holidays: 'Параметри ЛР2'!$A$18:$A$19
Name cap_BA: 'Параметри ЛР2'!$E$22
Name capd_BA: 'Параметри ЛР2'!$D$22
Name cap_D1: 'Параметри ЛР2'!$E$23
Name capd_D1: 'Параметри ЛР2'!$D$23
Name cap_D2: 'Параметри ЛР2'!$E$24
Name capd_D2: 'Параметри ЛР2'!$D$24
Name cap_QA: 'Параметри ЛР2'!$E$25
Name capd_QA: 'Параметри ЛР2'!$D$25
Name cap_OPS: 'Параметри ЛР2'!$E$26
Name capd_OPS: 'Параметри ЛР2'!$D$26
Name team_week: 'Параметри ЛР2'!$E$27
Name team_day: 'Параметри ЛР2'!$D$27
Name proj_end: 'WBS і CPM'!$S$23
Name bl_days: 'PERT і резерв'!$B$18
Name bl_p50: 'PERT і резерв'!$B$13
Name bl_p80: 'PERT і резерв'!$B$14
Name ucp_val: UCP!$D$37
Name ucp_effort: UCP!$D$39
Name ucp_weeks: UCP!$D$52

Sheet Параметри ЛР2
A1: Ім'я | B1: Показник | C1: Значення | D1: Одиниця | E1: Тип | F1: Пояснення
A2: p2_start | B2: Дата старту проєкту | C2: 46328 | D2: дата | E2: П | F2: після тестів A1, A2, A5 з ЛР № 1
A3: p2_hours | B3: Годин у робочому дні | C3: 8 | D3: год | E3: П | F3: повний робочий день
A4: p2_focus | B4: Частка продуктивного часу | C4: 0.7 | D4: частка | E4: П | F4: 30% наради, церемонії, комунікація; 3,75 FTE × 40 × 0,7 = 105
A5: p2_days_week | B5: Робочих днів на тиждень | C5: 5 | D5: днів | E5: П
A6: p2_z80 | B6: Квантиль N(0;1) рівня 0,8 | C6: =NORMSINV(0.8) | E6: Д | F6: методичка: 0,842
A7: p2_backlog | B7: Backlog | C7: 116 | D7: SP | E7: Д | F7: варіант 14
A8: p2_sprint | B8: Тривалість спринту | C8: 2 | D8: тиж. | E8: Д | F8: усі спринти 2 тижні
A9: p2_tcf | B9: TCF | C9: 0.9 | E9: Д | F9: варіант 14
A10: p2_ecf | B10: ECF | C10: 0.9 | E10: Д | F10: варіант 14
A11: p2_pf | B11: PF | C11: 22 | D11: люд.-год/UCP | E11: Д | F11: варіант 14
A12: p2_util | B12: Досяжне завантаження вузької ролі | C12: 0.85 | D12: частка | E12: П | F12: залежності і очікування; WBS дає 0,80 для розробників
A13: p2_mr | B13: Management reserve | C13: 15 | D13: роб. днів | E13: П | F13: системний сценарій нестабільних лічильників
A14: p2_mc_p50 | B14: P50 за симуляцією Монте-Карло | C14: 126.23 | D14: роб. днів | E14: Р | F14: 20 000 прогонів, seed 14, Python
A15: p2_mc_p80 | B15: P80 за симуляцією Монте-Карло | C15: 131.4 | D15: роб. днів | E15: Р | F15: 20 000 прогонів, seed 14, Python
A17: Неробочі дні
A18: 46387 | B18: команда бере 2 дні відпустки; державні свята в умовах воєнного стану не є вихідними
A19: 46388
A21: Роль | B21: Обов'язки | C21: FTE | D21: Год/день | E21: Год/тиждень
A22: BA/PM | B22: вимоги, backlog, критерії приймання, розмітка аномалій, комунікація з пілотною будівлею; UX прототипи дашборда | C22: 0.5 | D22: =C22*p2_hours*p2_focus | E22: =D22*p2_days_week
A23: Розробник 1 | B23: ПЗ шлюзу Modbus і MQTT, приймання показів, деградований режим, звіти і RBAC | C23: 1 | D23: =C23*p2_hours*p2_focus | E23: =D23*p2_days_week
A24: Розробник 2 | B24: реєстр, базова лінія, виявлення аномалій, сповіщення, інциденти, вебінтерфейс | C24: 1 | D24: =C24*p2_hours*p2_focus | E24: =D24*p2_days_week
A25: QA | B25: тест-стенд лічильників, автотести інтеграції, навантажувальні тести, приймання | C25: 0.75 | D25: =C25*p2_hours*p2_focus | E25: =D25*p2_days_week
A26: DevOps | B26: IaC, CI/CD, середовища, моніторинг, резервні копії, монтаж шлюзу в пілоті | C26: 0.5 | D26: =C26*p2_hours*p2_focus | E26: =D26*p2_days_week
A27: Разом | C27: =SUM(C22:C26) | D27: =SUM(D22:D26) | E27: =SUM(E22:E26)

Sheet Журнал scope
A1: ID | B1: Елемент ЛР № 1 | C1: Статус | D1: Зміна / причина | E1: Вплив
A2: S1 | B2: F1...F11, межі «поза MVP» | C2: без змін | D2: функції і 7 виключень перенесено з ЛР № 1 | E2: немає
A3: S2 | B3: NFR1...NFR5 | C3: без змін | D3: пороги перенесено; NFR1 і NFR4 оформлено окремим backlog item B12 (3 SP) | E3: +3 SP у backlog
A4: S3 | B4: F11 Звіт орендарю | C4: уточнено | D4: у MVP орендар отримує звіт файлом через пошту, без входу в GUI | E4: менше UC і актор орендаря не враховано в UCP
A5: S4 | B5: F5 Базова лінія | C5: уточнено | D5: медіана 4 однакових днів тижня потребує 28 діб історії | E5: у WBS додано пакет 5.4 з накопиченням історії паралельно з розробленням
A6: S5 | B6: F3 Деградований режим | C6: уточнено | D6: приймання на тест-стенді (5.1) і в пілоті (5.5) з реальними обривами | E6: залежність 2.4 від 5.1
A7: S6 | B7: F6 Виявлення аномалій | C7: уточнено | D7: precision і recall вимірюються спершу на історичних даних тесту A1, потім на 28 добах пілоту | E7: пакет 5.5
A8: S7 | B8: Команда MVP | C8: уточнено | D8: 5 осіб з ЛР № 1 отримали FTE: BA/PM 0,5; 2 розробники по 1,0; QA 0,75; DevOps 0,5; UX виконує BA/PM | E8: 3,75 FTE, 105 продуктивних люд.-год на тиждень
A9: S8 | B9: Припущення A5, A7, A12 | C9: уточнено | D9: A12 і пакетний аспект A5 включено в P пакетів 1.2, 2.4; системний сценарій A5 винесено в management reserve | E9: без подвійного обліку ризику

Sheet WBS і CPM
A1: ID | B1: Пакет / результат | C1: Попередник | D1: Лідер | E1: BA/PM, год | F1: Розр. 1, год | G1: Розр. 2, год | H1: QA, год | I1: DevOps, год | J1: Effort M, год | K1: O, днів | L1: M, днів | M1: P, днів | N1: E, днів | O1: σ, днів | P1: Var, дні² | Q1: Effort E, год | R1: ES | S1: EF | T1: LS | U1: LF | V1: Резерв | W1: Критичний | X1: Старт | Y1: Фініш | Z1: DoD
A2: 1.1 | B2: Scope freeze: уточнений backlog і критерії приймання | C2: немає | D2: BA/PM | E2: 22 | F2: 10 | G2: 10 | H2: 10 | I2: 6 | J2: =SUM(E2:I2) | K2: 6 | L2: 8 | M2: 12 | N2: =(K2+4*L2+M2)/6 | O2: =(M2-K2)/6 | P2: =O2^2 | Q2: =J2*N2/L2 | R2: 0 | S2: =R2+N2 | T2: =U2-N2 | U2: =MIN(proj_end,T3-0) | V2: =T2-R2 | W2: =IF(ABS(V2)<0.001,"так","ні") | X2: =WORKDAY(p2_start,ROUNDDOWN(R2,0),p2_holidays) | Y2: =WORKDAY(p2_start,ROUNDUP(S2,0)-1,p2_holidays) | Z2: 116 SP оцінено командою, критерії приймання F1...F11 і NFR1...NFR5 погоджено, журнал змін scope підписано
A3: 1.2 | B3: Architecture spike: прототип шлюзу і вибір сховища | C3: 1.1 | D3: Розробник 1 | E3: 8 | F3: 64 | G3: 56 | H3: 12 | I3: 24 | J3: =SUM(E3:I3) | K3: 8 | L3: 12 | M3: 24 | N3: =(K3+4*L3+M3)/6 | O3: =(M3-K3)/6 | P3: =O3^2 | Q3: =J3*N3/L3 | R3: =MAX(0,S2+0) | S3: =R3+N3 | T3: =U3-N3 | U3: =MIN(proj_end,T4-0,T5-0,T6-0,T16-5+N3) | V3: =T3-R3 | W3: =IF(ABS(V3)<0.001,"так","ні") | X3: =WORKDAY(p2_start,ROUNDDOWN(R3,0),p2_holidays) | Y3: =WORKDAY(p2_start,ROUNDUP(S3,0)-1,p2_holidays) | Z3: прототип зчитав 3 типи лічильників по Modbus RTU/TCP; ADR щодо БД часових рядів; тест приймання 30 × 96 записів на добу
A4: 1.3 | B4: Інфраструктура: IaC, CI/CD, середовища, моніторинг | C4: 1.2 | D4: DevOps | E4: 0 | F4: 0 | G4: 0 | H4: 4 | I4: 52 | J4: =SUM(E4:I4) | K4: 18 | L4: 25 | M4: 35 | N4: =(K4+4*L4+M4)/6 | O4: =(M4-K4)/6 | P4: =O4^2 | Q4: =J4*N4/L4 | R4: =MAX(0,S3+0) | S4: =R4+N4 | T4: =U4-N4 | U4: =MIN(proj_end,T19-0) | V4: =T4-R4 | W4: =IF(ABS(V4)<0.001,"так","ні") | X4: =WORKDAY(p2_start,ROUNDDOWN(R4,0),p2_holidays) | Y4: =WORKDAY(p2_start,ROUNDUP(S4,0)-1,p2_holidays) | Z4: середовища dev, stage, prod створюються з коду; конвеєр CI/CD до 15 хв; моніторинг і резервні копії (NFR3)
A5: 2.1 | B5: F1 Реєстр будівлі й лічильників | C5: 1.2 | D5: Розробник 2 | E5: 8 | F5: 0 | G5: 60 | H5: 16 | I5: 2 | J5: =SUM(E5:I5) | K5: 9 | L5: 11 | M5: 15 | N5: =(K5+4*L5+M5)/6 | O5: =(M5-K5)/6 | P5: =O5^2 | Q5: =J5*N5/L5 | R5: =MAX(0,S3+0) | S5: =R5+N5 | T5: =U5-N5 | U5: =MIN(proj_end,T9-0) | V5: =T5-R5 | W5: =IF(ABS(V5)<0.001,"так","ні") | X5: =WORKDAY(p2_start,ROUNDDOWN(R5,0),p2_holidays) | Y5: =WORKDAY(p2_start,ROUNDUP(S5,0)-1,p2_holidays) | Z5: дерево ввід, поверх, орендар, споживач без циклів; 30 лічильників описано за 2 год
A6: 2.2 | B6: F2 ПЗ шлюзу: опитування Modbus, імпульсні входи, MQTT 5 | C6: 1.2 | D6: Розробник 1 | E6: 6 | F6: 86 | G6: 0 | H6: 20 | I6: 6 | J6: =SUM(E6:I6) | K6: 13 | L6: 16 | M6: 25 | N6: =(K6+4*L6+M6)/6 | O6: =(M6-K6)/6 | P6: =O6^2 | Q6: =J6*N6/L6 | R6: =MAX(0,S3+0) | S6: =R6+N6 | T6: =U6-N6 | U6: =MIN(proj_end,T7-0) | V6: =T6-R6 | W6: =IF(ABS(V6)<0.001,"так","ні") | X6: =WORKDAY(p2_start,ROUNDDOWN(R6,0),p2_holidays) | Y6: =WORKDAY(p2_start,ROUNDUP(S6,0)-1,p2_holidays) | Z6: на тест-стенді не менше 99% інтервалів доставлено за 7 діб стабільного зв'язку
A7: 2.3 | B7: F4 Приймання показів і контроль якості | C7: 2.2 | D7: Розробник 1 | E7: 6 | F7: 72 | G7: 0 | H7: 19 | I7: 4 | J7: =SUM(E7:I7) | K7: 11 | L7: 13 | M7: 19 | N7: =(K7+4*L7+M7)/6 | O7: =(M7-K7)/6 | P7: =O7^2 | Q7: =J7*N7/L7 | R7: =MAX(0,S6+0) | S7: =R7+N7 | T7: =U7-N7 | U7: =MIN(proj_end,T8-0) | V7: =T7-R7 | W7: =IF(ABS(V7)<0.001,"так","ні") | X7: =WORKDAY(p2_start,ROUNDDOWN(R7,0),p2_holidays) | Y7: =WORKDAY(p2_start,ROUNDUP(S7,0)-1,p2_holidays) | Z7: 100% з 20 штучних помилкових записів позначено; інтервальне споживання як різниця накопичувальних показів
A8: 2.4 | B8: F3 Деградований режим: буфер 72 год, дозавантаження | C8: 2.3, 5.1 | D8: Розробник 1 | E8: 6 | F8: 88 | G8: 0 | H8: 28 | I8: 6 | J8: =SUM(E8:I8) | K8: 13 | L8: 16 | M8: 31 | N8: =(K8+4*L8+M8)/6 | O8: =(M8-K8)/6 | P8: =O8^2 | Q8: =J8*N8/L8 | R8: =MAX(0,S7+0,S16+0) | S8: =R8+N8 | T8: =U8-N8 | U8: =MIN(proj_end,T14-0,T19-0) | V8: =T8-R8 | W8: =IF(ABS(V8)<0.001,"так","ні") | X8: =WORKDAY(p2_start,ROUNDDOWN(R8,0),p2_holidays) | Y8: =WORKDAY(p2_start,ROUNDUP(S8,0)-1,p2_holidays) | Z8: після обривів 1, 6, 24 год дозавантажено не менше 99,5% інтервалів за 30 хв; 0 хибних алертів на прогалинах
A9: 3.1 | B9: F5 Базова лінія | C9: 2.1 | D9: Розробник 2 | E9: 8 | F9: 0 | G9: 60 | H9: 13 | I9: 2 | J9: =SUM(E9:I9) | K9: 9 | L9: 11 | M9: 16 | N9: =(K9+4*L9+M9)/6 | O9: =(M9-K9)/6 | P9: =O9^2 | Q9: =J9*N9/L9 | R9: =MAX(0,S5+0) | S9: =R9+N9 | T9: =U9-N9 | U9: =MIN(proj_end,T10-0) | V9: =T9-R9 | W9: =IF(ABS(V9)<0.001,"так","ні") | X9: =WORKDAY(p2_start,ROUNDDOWN(R9,0),p2_holidays) | Y9: =WORKDAY(p2_start,ROUNDUP(S9,0)-1,p2_holidays) | Z9: медіана 4 однакових днів тижня і MAD для 30 лічильників розраховуються не довше 60 с
A10: 3.2 | B10: F6 Виявлення аномалій | C10: 3.1 | D10: Розробник 2 | E10: 20 | F10: 0 | G10: 88 | H10: 24 | I10: 2 | J10: =SUM(E10:I10) | K10: 11 | L10: 16 | M10: 29 | N10: =(K10+4*L10+M10)/6 | O10: =(M10-K10)/6 | P10: =O10^2 | Q10: =J10*N10/L10 | R10: =MAX(0,S9+0) | S10: =R10+N10 | T10: =U10-N10 | U10: =MIN(proj_end,T11-0) | V10: =T10-R10 | W10: =IF(ABS(V10)<0.001,"так","ні") | X10: =WORKDAY(p2_start,ROUNDDOWN(R10,0),p2_holidays) | Y10: =WORKDAY(p2_start,ROUNDUP(S10,0)-1,p2_holidays) | Z10: на розмічених історичних даних precision не менше 0,8, recall не менше 0,7
A11: 3.3 | B11: F7 Сповіщення і ескалація | C11: 3.2 | D11: Розробник 2 | E11: 4 | F11: 0 | G11: 50 | H11: 14 | I11: 4 | J11: =SUM(E11:I11) | K11: 7 | L11: 9 | M11: 13 | N11: =(K11+4*L11+M11)/6 | O11: =(M11-K11)/6 | P11: =O11^2 | Q11: =J11*N11/L11 | R11: =MAX(0,S10+0) | S11: =R11+N11 | T11: =U11-N11 | U11: =MIN(proj_end,T12-0) | V11: =T11-R11 | W11: =IF(ABS(V11)<0.001,"так","ні") | X11: =WORKDAY(p2_start,ROUNDDOWN(R11,0),p2_holidays) | Y11: =WORKDAY(p2_start,ROUNDUP(S11,0)-1,p2_holidays) | Z11: 95% сповіщень надіслано до 2 хв після фіксації аномалії; ескалація SMS після 30 хв без підтвердження
A12: 4.1 | B12: F8 Картка інциденту | C12: 3.3 | D12: Розробник 2 | E12: 8 | F12: 0 | G12: 60 | H12: 18 | I12: 2 | J12: =SUM(E12:I12) | K12: 9 | L12: 11 | M12: 15 | N12: =(K12+4*L12+M12)/6 | O12: =(M12-K12)/6 | P12: =O12^2 | Q12: =J12*N12/L12 | R12: =MAX(0,S11+0) | S12: =R12+N12 | T12: =U12-N12 | U12: =MIN(proj_end,T13-0) | V12: =T12-R12 | W12: =IF(ABS(V12)<0.001,"так","ні") | X12: =WORKDAY(p2_start,ROUNDDOWN(R12,0),p2_holidays) | Y12: =WORKDAY(p2_start,ROUNDUP(S12,0)-1,p2_holidays) | Z12: інцидент закривається лише з причиною з довідника; фіксується збережений обсяг кВт·год
A13: 4.2 | B13: F9 Дашборд будівлі | C13: 4.1 | D13: Розробник 2 | E13: 10 | F13: 0 | G13: 82 | H13: 22 | I13: 4 | J13: =SUM(E13:I13) | K13: 11 | L13: 15 | M13: 23 | N13: =(K13+4*L13+M13)/6 | O13: =(M13-K13)/6 | P13: =O13^2 | Q13: =J13*N13/L13 | R13: =MAX(0,S12+0) | S13: =R13+N13 | T13: =U13-N13 | U13: =MIN(proj_end,T17-0) | V13: =T13-R13 | W13: =IF(ABS(V13)<0.001,"так","ні") | X13: =WORKDAY(p2_start,ROUNDDOWN(R13,0),p2_holidays) | Y13: =WORKDAY(p2_start,ROUNDUP(S13,0)-1,p2_holidays) | Z13: звіт за 30 діб для 30 лічильників (86 400 точок) відкривається до 2 с
A14: 4.3 | B14: F10 Імпорт рахунку і звірка з вводом | C14: 2.4 | D14: Розробник 1 | E14: 6 | F14: 38 | G14: 0 | H14: 12 | I14: 2 | J14: =SUM(E14:I14) | K14: 6 | L14: 7 | M14: 10 | N14: =(K14+4*L14+M14)/6 | O14: =(M14-K14)/6 | P14: =O14^2 | Q14: =J14*N14/L14 | R14: =MAX(0,S8+0) | S14: =R14+N14 | T14: =U14-N14 | U14: =MIN(proj_end,T15-0) | V14: =T14-R14 | W14: =IF(ABS(V14)<0.001,"так","ні") | X14: =WORKDAY(p2_start,ROUNDDOWN(R14,0),p2_holidays) | Y14: =WORKDAY(p2_start,ROUNDUP(S14,0)-1,p2_holidays) | Z14: розбіжність понад 3% між рахунком і лічильником вводу позначається для перевірки
A15: 4.4 | B15: F11 Звіт орендарю і ролі доступу | C15: 4.3 | D15: Розробник 1 | E15: 6 | F15: 60 | G15: 0 | H15: 18 | I15: 4 | J15: =SUM(E15:I15) | K15: 9 | L15: 11 | M15: 16 | N15: =(K15+4*L15+M15)/6 | O15: =(M15-K15)/6 | P15: =O15^2 | Q15: =J15*N15/L15 | R15: =MAX(0,S14+0) | S15: =R15+N15 | T15: =U15-N15 | U15: =MIN(proj_end,T17-0) | V15: =T15-R15 | W15: =IF(ABS(V15)<0.001,"так","ні") | X15: =WORKDAY(p2_start,ROUNDDOWN(R15,0),p2_holidays) | Y15: =WORKDAY(p2_start,ROUNDUP(S15,0)-1,p2_holidays) | Z15: PDF і CSV по власних точках обліку; 100% тестів RBAC пройдено; MFA для адміністраторів
A16: 5.1 | B16: Тест-стенд: 6 типів лічильників і імітатор обривів | C16: 1.2 SS+5 | D16: QA | E16: 0 | F16: 0 | G16: 0 | H16: 30 | I16: 4 | J16: =SUM(E16:I16) | K16: 15 | L16: 22 | M16: 32 | N16: =(K16+4*L16+M16)/6 | O16: =(M16-K16)/6 | P16: =O16^2 | Q16: =J16*N16/L16 | R16: =MAX(0,R3+5) | S16: =R16+N16 | T16: =U16-N16 | U16: =MIN(proj_end,T8-0) | V16: =T16-R16 | W16: =IF(ABS(V16)<0.001,"так","ні") | X16: =WORKDAY(p2_start,ROUNDDOWN(R16,0),p2_holidays) | Y16: =WORKDAY(p2_start,ROUNDUP(S16,0)-1,p2_holidays) | Z16: стенд RS-485 з 6 типами лічильників, керований імітатор обривів зв'язку, автотести інтеграції в CI
A17: 5.2 | B17: Feature complete: системне і навантажувальне тестування | C17: 4.2, 4.4 | D17: QA | E17: 8 | F17: 24 | G17: 24 | H17: 40 | I17: 10 | J17: =SUM(E17:I17) | K17: 8 | L17: 10 | M17: 16 | N17: =(K17+4*L17+M17)/6 | O17: =(M17-K17)/6 | P17: =O17^2 | Q17: =J17*N17/L17 | R17: =MAX(0,S13+0,S15+0) | S17: =R17+N17 | T17: =U17-N17 | U17: =MIN(proj_end,T18-0,T20-0) | V17: =T17-R17 | W17: =IF(ABS(V17)<0.001,"так","ні") | X17: =WORKDAY(p2_start,ROUNDDOWN(R17,0),p2_holidays) | Y17: =WORKDAY(p2_start,ROUNDUP(S17,0)-1,p2_holidays) | Z17: усі критерії приймання F1...F11 перевірено; NFR1 і NFR4 підтверджено навантажувальним тестом на 20 користувачах
A18: 5.3 | B18: Стабілізація: виправлення дефектів і пентест RBAC | C18: 5.2 | D18: Розробник 1 | E18: 4 | F18: 46 | G18: 46 | H18: 30 | I18: 8 | J18: =SUM(E18:I18) | K18: 7 | L18: 10 | M18: 20 | N18: =(K18+4*L18+M18)/6 | O18: =(M18-K18)/6 | P18: =O18^2 | Q18: =J18*N18/L18 | R18: =MAX(0,S17+0) | S18: =R18+N18 | T18: =U18-N18 | U18: =MIN(proj_end,T21-0) | V18: =T18-R18 | W18: =IF(ABS(V18)<0.001,"так","ні") | X18: =WORKDAY(p2_start,ROUNDDOWN(R18,0),p2_holidays) | Y18: =WORKDAY(p2_start,ROUNDUP(S18,0)-1,p2_holidays) | Z18: 0 відкритих дефектів критичного і високого рівня; звіт пентесту RBAC без критичних знахідок
A19: 5.4 | B19: Пілот: монтаж шлюзу і накопичення 4 тижнів історії | C19: 2.4, 1.3 | D19: DevOps | E19: 16 | F19: 6 | G19: 0 | H19: 4 | I19: 24 | J19: =SUM(E19:I19) | K19: 23 | L19: 25 | M19: 35 | N19: =(K19+4*L19+M19)/6 | O19: =(M19-K19)/6 | P19: =O19^2 | Q19: =J19*N19/L19 | R19: =MAX(0,S8+0,S4+0) | S19: =R19+N19 | T19: =U19-N19 | U19: =MIN(proj_end,T20-0) | V19: =T19-R19 | W19: =IF(ABS(V19)<0.001,"так","ні") | X19: =WORKDAY(p2_start,ROUNDDOWN(R19,0),p2_holidays) | Y19: =WORKDAY(p2_start,ROUNDUP(S19,0)-1,p2_holidays) | Z19: шлюз і 30 лічильників у пілотній будівлі передають дані; накопичено 28 діб історії для базової лінії F5
A20: 5.5 | B20: Пілотна валідація на реальних даних | C20: 5.4, 5.2 | D20: BA/PM | E20: 18 | F20: 4 | G20: 6 | H20: 8 | I20: 4 | J20: =SUM(E20:I20) | K20: 7 | L20: 10 | M20: 16 | N20: =(K20+4*L20+M20)/6 | O20: =(M20-K20)/6 | P20: =O20^2 | Q20: =J20*N20/L20 | R20: =MAX(0,S19+0,S17+0) | S20: =R20+N20 | T20: =U20-N20 | U20: =MIN(proj_end,T21-0) | V20: =T20-R20 | W20: =IF(ABS(V20)<0.001,"так","ні") | X20: =WORKDAY(p2_start,ROUNDDOWN(R20,0),p2_holidays) | Y20: =WORKDAY(p2_start,ROUNDUP(S20,0)-1,p2_holidays) | Z20: F6 на 28 добах реальних даних: precision не менше 0,8; F3: реальні обриви дозавантажено не менше 99,5%
A21: 5.6 | B21: Release readiness: документація, навчання, go/no-go | C21: 5.3, 5.5 | D21: BA/PM | E21: 14 | F21: 4 | G21: 4 | H21: 6 | I21: 14 | J21: =SUM(E21:I21) | K21: 4 | L21: 5 | M21: 8 | N21: =(K21+4*L21+M21)/6 | O21: =(M21-K21)/6 | P21: =O21^2 | Q21: =J21*N21/L21 | R21: =MAX(0,S18+0,S20+0) | S21: =R21+N21 | T21: =U21-N21 | U21: =proj_end | V21: =T21-R21 | W21: =IF(ABS(V21)<0.001,"так","ні") | X21: =WORKDAY(p2_start,ROUNDDOWN(R21,0),p2_holidays) | Y21: =WORKDAY(p2_start,ROUNDUP(S21,0)-1,p2_holidays) | Z21: runbook, інструкція енергоменеджера, навчання 1 год, рішення go/no-go власника пілотної будівлі
A23: Разом | B23: тривалість проєкту за E, роб. днів; effort, год | E23: =SUM(E2:E21) | F23: =SUM(F2:F21) | G23: =SUM(G2:G21) | H23: =SUM(H2:H21) | I23: =SUM(I2:I21) | J23: =SUM(J2:J21) | Q23: =SUM(Q2:Q21) | S23: =MAX(S2:S21) | V23: =COUNTIF(W2:W21,"так") | W23: критичних

Sheet PERT і резерв
A1: ID | B1: Пакет | C1: O | D1: M | E1: P | F1: E | G1: σ | H1: Var | I1: Критичний | J1: Пояснення P
A2: 1.2 | B2: Architecture spike: прототип шлюзу і вибір сховища | C2: ='WBS і CPM'!K3 | D2: ='WBS і CPM'!L3 | E2: ='WBS і CPM'!M3 | F2: =(C2+4*D2+E2)/6 | G2: =(E2-C2)/6 | H2: =G2^2 | I2: ='WBS і CPM'!W3 | J2: ключова невизначеність варіанта: карта регістрів Modbus надходить від постачальника лічильників (A12), частина лічильників відповідає нестабільно; у P закладено 2 ітерації очікування по 5 робочих днів
A3: 2.4 | B3: F3 Деградований режим: буфер 72 год, дозавантаження | C3: ='WBS і CPM'!K8 | D3: ='WBS і CPM'!L8 | E3: ='WBS і CPM'!M8 | F3: =(C3+4*D3+E3)/6 | G3: =(E3-C3)/6 | H3: =G3^2 | I3: ='WBS і CPM'!W8 | J3: ключова невизначеність варіанта на рівні пакета: поведінка конкретних лічильників після перезапуску (скидання лічильника, перехід через нуль), ідемпотентність дозавантаження
A4: 3.2 | B4: F6 Виявлення аномалій | C4: ='WBS і CPM'!K10 | D4: ='WBS і CPM'!L10 | E4: ='WBS і CPM'!M10 | F4: =(C4+4*D4+E4)/6 | G4: =(E4-C4)/6 | H4: =G4^2 | I4: ='WBS і CPM'!W10 | J4: поріг max(3σ; 10%) може потребувати 2...3 циклів налаштування на розмічених даних (A7)
A5: 4.2 | B5: F9 Дашборд будівлі | C5: ='WBS і CPM'!K13 | D5: ='WBS і CPM'!L13 | E5: ='WBS і CPM'!M13 | F5: =(C5+4*D5+E5)/6 | G5: =(E5-C5)/6 | H5: =G5^2 | I5: ='WBS і CPM'!W13 | J5: агрегування 86 400 точок до 2 с може вимагати попередньо обчислених агрегатів
A6: 5.2 | B6: Feature complete: системне і навантажувальне тестування | C6: ='WBS і CPM'!K17 | D6: ='WBS і CPM'!L17 | E6: ='WBS і CPM'!M17 | F6: =(C6+4*D6+E6)/6 | G6: =(E6-C6)/6 | H6: =G6^2 | I6: ='WBS і CPM'!W17
A7: 5.3 | B7: Стабілізація: виправлення дефектів і пентест RBAC | C7: ='WBS і CPM'!K18 | D7: ='WBS і CPM'!L18 | E7: ='WBS і CPM'!M18 | F7: =(C7+4*D7+E7)/6 | G7: =(E7-C7)/6 | H7: =G7^2 | I7: ='WBS і CPM'!W18 | J7: кількість дефектів після інтеграції з реальними лічильниками невідома до 5.2
A9: Показник | B9: Значення | C9: Одиниця | D9: Пояснення
A10: μ = ΣE критичного шляху | B10: =SUMIF('WBS і CPM'!$W$2:$W$21,"так",'WBS і CPM'!$N$2:$N$21) | C10: роб. днів | D10: P50 ≈ μ
A11: ΣVar критичного шляху | B11: =SUMIF('WBS і CPM'!$W$2:$W$21,"так",'WBS і CPM'!$P$2:$P$21) | C11: дні²
A12: σ шляху | B12: =SQRT(B11) | C12: роб. днів | D12: √ΣVar
A13: P50 | B13: =B10 | C13: роб. днів | D13: аналітично
A14: P80 | B14: =B10+p2_z80*B12 | C14: роб. днів | D14: μ + 0,842σ
A15: Contingency за формулою | B15: =B14-B13 | C15: роб. днів | D15: P80 − P50
A16: Контроль: кінець мережі за CPM | B16: =proj_end | C16: роб. днів | D16: має дорівнювати μ
A17: P80 за Монте-Карло | B17: =p2_mc_p80 | C17: роб. днів | D17: враховує злиття шляхів
A18: Baseline | B18: =ROUNDUP(MAX(B14,B17),0) | C18: роб. днів | D18: більше з двох P80, ціле
A19: Contingency у baseline | B19: =B18-B13 | C19: роб. днів | D19: baseline − P50
A20: Management reserve | B20: =p2_mr | C20: роб. днів | D20: поза baseline
A21: Дата старту | B21: =p2_start | C21: дата
A22: Дата P50 | B22: =WORKDAY(p2_start,ROUNDUP(B13,0)-1,p2_holidays) | C22: дата
A23: Baseline-дата | B23: =WORKDAY(p2_start,B18-1,p2_holidays) | C23: дата | D23: з contingency
A24: Дата з management reserve | B24: =WORKDAY(p2_start,B18+B20-1,p2_holidays) | C24: дата | D24: межа рішення спонсора
A25: Baseline, тижнів | B25: =B18/p2_days_week | C25: тиж.

Sheet Backlog і velocity
A1: ID | B1: Backlog item | C1: SP | D1: Пакет WBS | F1: Чому така оцінка
A2: B1 | B2: F1 Реєстр будівлі й лічильників | C2: 8 | D2: 2.1 | F2: CRUD з деревом і перевіркою циклів, імпорт карти регістрів
A3: B2 | B3: F2 ПЗ шлюзу Modbus і MQTT | C3: 13 | D3: 2.2 | F3: два протоколи, імпульсні входи, QoS 1, невідомі реалізації Modbus
A4: B3 | B4: F3 Деградований режим | C4: 13 | D4: 2.4 | F4: буфер, ідемпотентне дозавантаження, статуси якості, ключова невизначеність
A5: B4 | B5: F4 Приймання показів і контроль якості | C5: 13 | D5: 2.3 | F5: чотири правила якості, перехід через нуль, різниця накопичувальних показів
A6: B5 | B6: F5 Базова лінія | C6: 8 | D6: 3.1 | F6: медіана і MAD по 96 слотах, перерахунок за розкладом
A7: B6 | B7: F6 Виявлення аномалій | C7: 13 | D7: 3.2 | F7: правило 4 інтервалів, нічне навантаження, налаштування порогу на розмічених даних
A8: B7 | B8: F7 Сповіщення і ескалація | C8: 8 | D8: 3.3 | F8: три канали, ескалація, оцінка перевитрати в кВт·год і EUR
A9: B8 | B9: F8 Картка інциденту | C9: 8 | D9: 4.1 | F9: життєвий цикл інциденту, довідник причин, підтвердження повернення до бази
A10: B9 | B10: F9 Дашборд будівлі | C10: 13 | D10: 4.2 | F10: профіль доби, факт і база, топ 5 споживачів, продуктивність 2 с
A11: B10 | B11: F10 Імпорт рахунку і звірка | C11: 8 | D11: 4.3 | F11: формат CSV двох постачальників, звірка з лічильником вводу, межі розрахункового періоду
A12: B11 | B12: F11 Звіт орендарю і ролі доступу | C12: 8 | D12: 4.4 | F12: PDF і CSV, RBAC, MFA для адміністраторів
A13: B12 | B13: NFR1 і NFR4: затримка і навантаження | C13: 3 | D13: 5.2 | F13: сценарій k6 і панелі затримки, без нової функціональності
A14: Разом | B14: =IF(C14=p2_backlog,"Разом: збігається з варіантом","Разом: розбіжність") | C14: =SUM(C2:C13)
A16: Спринт | B16: Velocity, SP
A17: S1 | B17: 17
A18: S2 | B18: 19
A19: S3 | B19: 16
A20: S4 | B20: 21
A21: S5 | B21: 18
A22: S6 | B22: 20
A24: Сценарій | B24: Velocity, SP | C24: Backlog / v | D24: Спринтів | E24: Тижні
A25: Fast: max | B25: =MAX(B17:B22) | C25: =p2_backlog/B25 | D25: =ROUNDUP(p2_backlog/B25,0) | E25: =D25*p2_sprint
A26: Central: медіана | B26: =MEDIAN(B17:B22) | C26: =p2_backlog/B26 | D26: =ROUNDUP(p2_backlog/B26,0) | E26: =D26*p2_sprint
A27: Slow: min | B27: =MIN(B17:B22) | C27: =p2_backlog/B27 | D27: =ROUNDUP(p2_backlog/B27,0) | E27: =D27*p2_sprint
A29: Повна тривалість | B29: До спринтів (1.1, 1.2), роб. днів | C29: Спринти, днів | D29: Після FC, днів | E29: Тижнів
A30: Fast | B30: ='WBS і CPM'!S3 | C30: =E25*p2_days_week | D30: =proj_end-MAX('WBS і CPM'!S5,'WBS і CPM'!S6,'WBS і CPM'!S7,'WBS і CPM'!S8,'WBS і CPM'!S9,'WBS і CPM'!S10,'WBS і CPM'!S11,'WBS і CPM'!S12,'WBS і CPM'!S13,'WBS і CPM'!S14,'WBS і CPM'!S15) | E30: =(B30+C30+D30)/p2_days_week
A31: Central | B31: ='WBS і CPM'!S3 | C31: =E26*p2_days_week | D31: =proj_end-MAX('WBS і CPM'!S5,'WBS і CPM'!S6,'WBS і CPM'!S7,'WBS і CPM'!S8,'WBS і CPM'!S9,'WBS і CPM'!S10,'WBS і CPM'!S11,'WBS і CPM'!S12,'WBS і CPM'!S13,'WBS і CPM'!S14,'WBS і CPM'!S15) | E31: =(B31+C31+D31)/p2_days_week
A32: Slow | B32: ='WBS і CPM'!S3 | C32: =E27*p2_days_week | D32: =proj_end-MAX('WBS і CPM'!S5,'WBS і CPM'!S6,'WBS і CPM'!S7,'WBS і CPM'!S8,'WBS і CPM'!S9,'WBS і CPM'!S10,'WBS і CPM'!S11,'WBS і CPM'!S12,'WBS і CPM'!S13,'WBS і CPM'!S14,'WBS і CPM'!S15) | E32: =(B32+C32+D32)/p2_days_week

Sheet UCP
A1: Актор | B1: Тип S/A/C | C1: Правило | D1: Вага
A2: SMS-шлюз (REST API) | B2: S | C2: системний API | D2: =IF(B2="S",1,IF(B2="A",2,3))
A3: Сервіс транзакційної пошти (REST API) | B3: S | C3: системний API | D3: =IF(B3="S",1,IF(B3="A",2,3))
A4: Bot API месенджера | B4: S | C4: системний API | D4: =IF(B4="S",1,IF(B4="A",2,3))
A5: Шлюз з лічильниками (Modbus RTU/TCP, MQTT 5) | B5: A | C5: взаємодія через протокол | D5: =IF(B5="S",1,IF(B5="A",2,3))
A6: Енергоменеджер або власник (адміністративна роль будівлі) | B6: C | C6: людина через GUI | D6: =IF(B6="S",1,IF(B6="A",2,3))
A7: Технік служби експлуатації | B7: C | C7: людина через GUI | D7: =IF(B7="S",1,IF(B7="A",2,3))
A9: Use case | B9: Транзакцій | C9: Функція | D9: Тип S/A/C | E9: Вага
A10: UC1 Зареєструвати будівлю і ієрархію лічильників | B10: 6 | C10: F1 | D10: =IF(B10<=3,"S",IF(B10<=7,"A","C")) | E10: =IF(D10="S",5,IF(D10="A",10,15))
A11: UC2 Налаштувати шлюз і розклад опитування | B11: 5 | C11: F2 | D11: =IF(B11<=3,"S",IF(B11<=7,"A","C")) | E11: =IF(D11="S",5,IF(D11="A",10,15))
A12: UC3 Передати пакет показів | B12: 3 | C12: F2 | D12: =IF(B12<=3,"S",IF(B12<=7,"A","C")) | E12: =IF(D12="S",5,IF(D12="A",10,15))
A13: UC4 Дозавантажити буфер після обриву зв'язку | B13: 9 | C13: F3 | D13: =IF(B13<=3,"S",IF(B13<=7,"A","C")) | E13: =IF(D13="S",5,IF(D13="A",10,15))
A14: UC5 Перевірити якість показу | B14: 5 | C14: F4 | D14: =IF(B14<=3,"S",IF(B14<=7,"A","C")) | E14: =IF(D14="S",5,IF(D14="A",10,15))
A15: UC6 Перерахувати базову лінію | B15: 4 | C15: F5 | D15: =IF(B15<=3,"S",IF(B15<=7,"A","C")) | E15: =IF(D15="S",5,IF(D15="A",10,15))
A16: UC7 Виявити аномалію і оцінити перевитрату | B16: 8 | C16: F6 | D16: =IF(B16<=3,"S",IF(B16<=7,"A","C")) | E16: =IF(D16="S",5,IF(D16="A",10,15))
A17: UC8 Надіслати сповіщення з ескалацією | B17: 6 | C17: F7 | D17: =IF(B17<=3,"S",IF(B17<=7,"A","C")) | E17: =IF(D17="S",5,IF(D17="A",10,15))
A18: UC9 Опрацювати інцидент до повернення до бази | B18: 10 | C18: F8 | D18: =IF(B18<=3,"S",IF(B18<=7,"A","C")) | E18: =IF(D18="S",5,IF(D18="A",10,15))
A19: UC10 Переглянути дашборд будівлі | B19: 3 | C19: F9 | D19: =IF(B19<=3,"S",IF(B19<=7,"A","C")) | E19: =IF(D19="S",5,IF(D19="A",10,15))
A20: UC11 Імпортувати рахунок і звірити з вводом | B20: 5 | C20: F10 | D20: =IF(B20<=3,"S",IF(B20<=7,"A","C")) | E20: =IF(D20="S",5,IF(D20="A",10,15))
A21: UC12 Сформувати і надіслати звіт орендарю | B21: 5 | C21: F11 | D21: =IF(B21<=3,"S",IF(B21<=7,"A","C")) | E21: =IF(D21="S",5,IF(D21="A",10,15))
... A24: UC15 Переглянути стан шлюзів і якість даних | B24: 2 | C24: F3, F4 | D24: =IF(B24<=3,"S",IF(B24<=7,"A","C")) | E24: =IF(D24="S",5,IF(D24="A",10,15))
A26: Компонент | B26: Кількість | C26: Вага | D26: Результат
A27: Прості актори | B27: =COUNTIF(B2:B7,"S") | C27: 1 | D27: =B27*C27
A28: Середні актори | B28: =COUNTIF(B2:B7,"A") | C28: 2 | D28: =B28*C28
A29: Складні актори | B29: =COUNTIF(B2:B7,"C") | C29: 3 | D29: =B29*C29
A30: UAW | D30: =SUM(D27:D29)
A31: Прості UC | B31: =COUNTIF(D10:D24,"S") | C31: 5 | D31: =B31*C31
A32: Середні UC | B32: =COUNTIF(D10:D24,"A") | C32: 10 | D32: =B32*C32
A33: Складні UC | B33: =COUNTIF(D10:D24,"C") | C33: 15 | D33: =B33*C33
A34: UUCW | D34: =SUM(D31:D33)
A35: UUCP | D35: =D30+D34
A36: TCF × ECF | B36: =p2_tcf | C36: =p2_ecf | D36: =B36*C36
A37: UCP | D37: =D35*D36
A38: PF, люд.-год/UCP | B38: =p2_pf | D38: =p2_pf
A39: Effort, люд.-год | D39: =D37*D38
A40: Effort при PF −20% | D40: =D37*p2_pf*0.8
A41: Effort при PF +20% | D41: =D37*p2_pf*1.2
A43: Роль | B43: Частка в WBS | C43: Effort, год | D43: Тижнів, PF 22 | E43: Тижнів, PF −20% | F43: Тижнів, PF +20%
A44: BA/PM | B44: ='WBS і CPM'!E23/'WBS і CPM'!J23 | C44: =ucp_effort*B44 | D44: =C44/cap_BA | E44: =D44*0.8 | F44: =D44*1.2
A45: Розробник 1 | B45: ='WBS і CPM'!F23/'WBS і CPM'!J23 | C45: =ucp_effort*B45 | D45: =C45/cap_D1 | E45: =D45*0.8 | F45: =D45*1.2
...

Sheet Календар
A1: Роль | B1: FTE | C1: Год/тиждень | D1: Год у WBS (E) | E1: Ємність за baseline, год | F1: Завантаження
A2: BA/PM | B2: 0.5 | C2: =cap_BA | D2: =SUMPRODUCT('WBS і CPM'!E2:E21,'WBS і CPM'!N2:N21/'WBS і CPM'!L2:L21) | E2: =C2*bl_days/p2_days_week | F2: =D2/E2
A3: Розробник 1 | B3: 1 | C3: =cap_D1 | D3: =SUMPRODUCT('WBS і CPM'!F2:F21,'WBS і CPM'!N2:N21/'WBS і CPM'!L2:L21) | E3: =C3*bl_days/p2_days_week | F3: =D3/E3
A4: Розробник 2 | B4: 1 | C4: =cap_D2 | D4: =SUMPRODUCT('WBS і CPM'!G2:G21,'WBS і CPM'!N2:N21/'WBS і CPM'!L2:L21) | E4: =C4*bl_days/p2_days_week | F4: =D4/E4
A5: QA | B5: 0.75 | C5: =cap_QA | D5: =SUMPRODUCT('WBS і CPM'!H2:H21,'WBS і CPM'!N2:N21/'WBS і CPM'!L2:L21) | E5: =C5*bl_days/p2_days_week | F5: =D5/E5
A6: DevOps | B6: 0.5 | C6: =cap_OPS | D6: =SUMPRODUCT('WBS і CPM'!I2:I21,'WBS і CPM'!N2:N21/'WBS і CPM'!L2:L21) | E6: =C6*bl_days/p2_days_week | F6: =D6/E6
A7: Команда | B7: =SUM(B2:B6) | C7: =SUM(C2:C6) | D7: =SUM(D2:D6) | E7: =SUM(E2:E6) | F7: =D7/E7
A9: Віха | B9: День (E) | C9: Дата
A10: Scope freeze | B10: =MAX('WBS і CPM'!S2) | C10: =WORKDAY(p2_start,ROUNDUP(B10,0)-1,p2_holidays)
A11: Architecture spike | B11: =MAX('WBS і CPM'!S3) | C11: =WORKDAY(p2_start,ROUNDUP(B11,0)-1,p2_holidays)
A12: Feature complete | B12: =MAX('WBS і CPM'!S5,'WBS і CPM'!S6,'WBS і CPM'!S7,'WBS і CPM'!S8,'WBS і CPM'!S9,'WBS і CPM'!S10,'WBS і CPM'!S11,'WBS і CPM'!S12,'WBS і CPM'!S13,'WBS і CPM'!S14,'WBS і CPM'!S15) | C12: =WORKDAY(p2_start,ROUNDUP(B12,0)-1,p2_holidays)
A13: Stabilization | B13: =MAX('WBS і CPM'!S18) | C13: =WORKDAY(p2_start,ROUNDUP(B13,0)-1,p2_holidays)
A14: Release readiness | B14: =MAX('WBS і CPM'!S21) | C14: =WORKDAY(p2_start,ROUNDUP(B14,0)-1,p2_holidays)
A15: Baseline (P80, з contingency) | B15: =bl_days | C15: =WORKDAY(p2_start,bl_days-1,p2_holidays)
A16: Межа з management reserve | B16: =bl_days+p2_mr | C16: =WORKDAY(p2_start,bl_days+p2_mr-1,p2_holidays)

Sheet Порівняння
A1: Метод | B1: Розмір | C1: Effort, год | D1: Тижнів: низ | E1: Тижнів: центр | F1: Тижнів: верх
A2: PERT/WBS | B2: =COUNTA('WBS і CPM'!A2:A21)&" пакетів" | C2: ='WBS і CPM'!Q23 | D2: =SUMIF('WBS і CPM'!W2:W21,"так",'WBS і CPM'!K2:K21)/p2_days_week | E2: =bl_p50/p2_days_week | F2: =bl_days/p2_days_week
A3: SP/velocity | B3: ='Backlog і velocity'!C14&" SP" | C3: не переводиться | D3: ='Backlog і velocity'!E30 | E3: ='Backlog і velocity'!E31 | F3: ='Backlog і velocity'!E32
A4: UCP/parametric | B4: =TEXT(ucp_val,"0.00")&" UCP" | C4: =ucp_effort | D4: =UCP!E52 | E4: =ucp_weeks | F4: =UCP!F52
